<mujoco model="NaoV6H25">
  <compiler meshdir="meshes" texturedir="textures" />
  <option timestep="0.003" integrator="RK4" />

  <default>
    <geom type="mesh" solref=".004 1" />
    <joint damping="1.084" armature="0.045" frictionloss="0.03" />
    <position
      kp="21.1"
      ctrllimited="true"
      forcerange="-5 5"
      forcelimited="true"
    />
    <!-- <general ctrllimited="false" forcelimited="true" forcerange="-30 30"/> -->
  </default>

  <asset>
    <texture name="ChestButton" type="2d" file="nao_torso_button_nao.png" />
    <texture name="Ear" type="2d" file="textures-ear.png" />

    <mesh file="naoHeadYaw_0.obj" />
    <mesh file="naoLAnklePitch_0.obj" />
    <mesh file="naoLAnkleRollV6_0.obj" />
    <mesh file="naoLAnkleRollV6_1.obj" />
    <mesh file="naoLAnkleRollV6_2.obj" />
    <mesh file="naoLAnkleRollV6_3.obj" />
    <mesh file="naoLElbowRoll_0.obj" />
    <mesh file="naoLHipPitch_0.obj" />
    <mesh file="naoLHipPitch_1.obj" />
    <mesh file="naoLHipRoll_0.obj" />
    <mesh file="naoLHipYawPitch_0.obj" />
    <mesh file="naoLHipYawPitch_1.obj" />
    <mesh file="naoLKneePitchV6_0.obj" />
    <mesh file="naoLKneePitchV6_1.obj" />
    <mesh file="naoLKneePitchV6_2.obj" />
    <mesh file="naoLShoulderPitch_0.obj" />
    <mesh file="naoLShoulderRollV6_0.obj" />
    <mesh file="naoLShoulderRollV6_1.obj" />
    <mesh file="naoLShoulderRollV6_2.obj" />
    <mesh file="naoRAnklePitch_0.obj" />
    <mesh file="naoRAnkleRollV6_0.obj" />
    <mesh file="naoRAnkleRollV6_1.obj" />
    <mesh file="naoRAnkleRollV6_2.obj" />
    <mesh file="naoRAnkleRollV6_3.obj" />
    <mesh file="naoRElbowRoll_0.obj" />
    <mesh file="naoRHipPitch_0.obj" />
    <mesh file="naoRHipPitch_1.obj" />
    <mesh file="naoRHipRoll_0.obj" />
    <mesh file="naoRHipYawPitch_0.obj" />
    <mesh file="naoRHipYawPitch_1.obj" />
    <mesh file="naoRKneePitchV6_0.obj" />
    <mesh file="naoRKneePitchV6_1.obj" />
    <mesh file="naoRKneePitchV6_2.obj" />
    <mesh file="naoRShoulderPitch_0.obj" />
    <mesh file="naoRShoulderRollV6_0.obj" />
    <mesh file="naoRShoulderRollV6_1.obj" />
    <mesh file="naoRShoulderRollV6_2.obj" />
    <mesh file="naoWristYawV6_0.obj" />
    <mesh file="naoWristYawV6_1.obj" />
    <mesh file="naoWristYawV6_2.obj" />
    <mesh file="naoHeadPitchV6_0.obj" />
    <mesh file="naoHeadPitchV6_1.obj" />
    <mesh file="naoHeadPitchV6_2.obj" />
    <mesh file="naoHeadPitchV6_3.obj" />
    <mesh file="naoHeadPitchV6_4.obj" />
    <mesh file="naoHeadPitchV6_5.obj" />
    <mesh file="naoTorsoV6_0.obj" />
    <mesh file="naoTorsoV6_jersey.obj" />
    <mesh file="naoTorsoV6_1.obj" />
    <mesh file="naoTorsoV6_2.obj" />
    <mesh file="naoTorsoV6_3.obj" />
    <mesh file="naoTorsoV6_4.obj" />

    <material name="nao-skin" rgba="0.5 0.5 0.5 1" />
    <material
      name="NaoMat_SecondarySkin_pantone445C"
      rgba="0.31 0.34 0.35 1"
      shininess="0.1"
    />
    <material
      name="NaoMat_Buton_nao_pantone445C"
      texture="ChestButton"
      shininess="0.1"
    />
    <material name="NaoMat_Structure" rgba="0.4 0.4 0.4 1" shininess="0.1" />
    <material name="NaoMat_MainSkin" rgba="0.6 0.6 0.6 1" />
    <material name="NaoMat_Sonar" rgba="0 0 0 1" shininess="0.1" />
    <material name="NaoMat_Reye" emission="1" />
    <material name="NaoMat_Leye" emission="1" />
    <material name="NaoMat_Pupil" rgba="0 0 0 1" />
    <material name="NaoMat_Hear" texture="Ear" />
  </asset>

  <worldbody>
    <body name="Nao" pos="0 0 0.314">
      <site name="root" />
      <geom type="mesh" material="NaoMat_MainSkin" mesh="naoTorsoV6_0" />
      <!-- <geom type="mesh" material="NaoMat_SecondarySkin_pantone445C" mesh="naoTorsoV6_1"/> -->
      <geom type="mesh" material="nao-skin" mesh="naoTorsoV6_jersey" />
      <geom type="mesh" material="NaoMat_Structure" mesh="naoTorsoV6_2" />
      <geom
        type="mesh"
        material="NaoMat_Buton_nao_pantone445C"
        mesh="naoTorsoV6_3"
      />
      <!-- <geom type="mesh" material="NaoMat_Sonar" mesh="naoTorsoV6_4"/> -->

      <inertial
        pos="-0.00413 0 0.04342"
        mass="1.04956"
        fullinertia="5062341.69e-9 4880133.93e-9 1610302.24e-9 14311.6e-9 155190.83e-9 -27079.3e-9"
      />
      <freejoint name="root" />

      <site name="inertial_measurement_unit" pos="-0.008 0.006 0.029" />
      <site name="Robot" pos="0 0 -0.085" />

      <body name="neck" pos="0 0 .1265">
        <geom type="mesh" material="NaoMat_Structure" mesh="naoHeadYaw_0" />

        <inertial
          pos="-0.00001 0 -0.02742"
          mass="0.07842"
          fullinertia="74992.98e-9 75999.99e-9 5533.73e-9 1.57e-9 -18.34e-9 -52.95e-9"
        />
        <joint
          name="head.yaw"
          axis="0 0 1"
          range="-119.5 119.5"
          limited="true"
        />

        <body name="head" pos="0 0 0">
          <site name="head_center" pos="0 0 0.053" />
          <geom
            type="mesh"
            material="NaoMat_SecondarySkin_pantone445C"
            mesh="naoHeadPitchV6_0"
          />
          <geom type="mesh" material="NaoMat_Pupil" mesh="naoHeadPitchV6_1" />
          <geom type="mesh" material="NaoMat_Hear" mesh="naoHeadPitchV6_2" />
          <geom type="mesh" material="NaoMat_Reye" mesh="naoHeadPitchV6_3" />
          <geom type="mesh" material="NaoMat_Leye" mesh="naoHeadPitchV6_4" />
          <geom
            type="mesh"
            material="NaoMat_MainSkin"
            mesh="naoHeadPitchV6_5"
          />

          <inertial
            pos="0.00109 0.00146 0.05719"
            mass="0.65973"
            fullinertia="2929818.72e-9 2838592.56e-9 716895.93e-9 3717.1e-9 -31446.71e-9 -73773.31e-9"
          />
          <joint
            name="head.pitch"
            axis="0 1 0"
            range="-38.5 29.5"
            limited="true"
          />
        </body>
      </body>

      <body name="left_hip_1" pos="0 0.05 -0.085">
        <geom
          type="mesh"
          material="NaoMat_Structure"
          mesh="naoLHipYawPitch_0"
        />
        <geom type="mesh" material="NaoMat_MainSkin" mesh="naoLHipYawPitch_1" />

        <inertial
          pos="-0.00781 -0.01114 0.02661"
          mass="0.06981"
          fullinertia="81502.27e-9 101325.27e-9 62623.96e-9 -4994.62e-9 12748.2e-9 23455.01e-9"
        />
        <joint
          name="left_leg.hip_yaw_pitch"
          axis="0 1 -1"
          range="-65.62 42.44"
          limited="true"
        />

        <body name="left_hip_2" pos="0 0 0">
          <geom type="mesh" material="NaoMat_Structure" mesh="naoLHipRoll_0" />

          <inertial
            pos="-0.01549 0.00029 -0.00515"
            mass="0.14053"
            fullinertia="27583.44e-9 98270.59e-9 88099.78e-9 -22.3e-9 -4081.53e-9 -4.18e-9"
          />
          <joint
            name="left_leg.hip_roll"
            axis="1 0 0"
            range="-21.74 45.29"
            limited="true"
          />

          <body name="left_thigh" pos="0 0 0">
            <geom
              type="mesh"
              material="NaoMat_Structure"
              mesh="naoLHipPitch_0"
            />
            <geom
              type="mesh"
              material="NaoMat_MainSkin"
              mesh="naoLHipPitch_1"
            />

            <inertial
              pos="0.00138 0.00221 -0.05373"
              mass="0.38968"
              fullinertia="1636719.24e-9 1591072.67e-9 303743.22e-9 924.45e-9 85310.79e-9 38357.47e-9"
            />
            <joint
              name="left_leg.hip_pitch"
              axis="0 1 0"
              range="-88 27.73"
              limited="true"
            />

            <body name="left_tibia" pos="0 0 -0.1">
              <geom
                type="mesh"
                material="NaoMat_MainSkin"
                mesh="naoLKneePitchV6_0"
              />
              <geom
                type="mesh"
                material="NaoMat_SecondarySkin_pantone445C"
                mesh="naoLKneePitchV6_1"
              />
              <geom
                type="mesh"
                material="NaoMat_Structure"
                mesh="naoLKneePitchV6_2"
              />

              <inertial
                pos="0.00453 0.00225 -0.04936"
                mass="0.30142"
                fullinertia="1182079.03e-9 1128652.24e-9 193227.6e-9 633.74e-9 36499.64e-9 39492.53e-9"
              />
              <joint
                name="left_leg.knee_pitch"
                axis="0 1 0"
                range="-5.29 121.04"
                limited="true"
              />

              <body name="left_ankle" pos="0 0 -0.1029">
                <geom
                  type="mesh"
                  material="NaoMat_Structure"
                  mesh="naoLAnklePitch_0"
                />

                <inertial
                  pos="0.00045 0.00029 0.00685"
                  mass="0.13416"
                  fullinertia="38509.81e-9 74265.29e-9 54865.35e-9 -26.34e-9 3861.96e-9 18.32e-9"
                />
                <joint
                  name="left_leg.ankle_pitch"
                  axis="0 1 0"
                  range="-68.15 52.86"
                  limited="true"
                />

                <body name="left_foot">
                  <geom
                    type="mesh"
                    material="NaoMat_MainSkin"
                    mesh="naoLAnkleRollV6_0"
                  />
                  <geom
                    type="mesh"
                    material="NaoMat_SecondarySkin_pantone445C"
                    mesh="naoLAnkleRollV6_1"
                  />
                  <geom
                    type="mesh"
                    material="NaoMat_Structure"
                    mesh="naoLAnkleRollV6_2"
                  />
                  <geom
                    type="mesh"
                    material="NaoMat_MainSkin"
                    mesh="naoLAnkleRollV6_3"
                  />

                  <inertial
                    pos="0.02542 0.0033 -0.03239"
                    mass="0.17184"
                    fullinertia="269442.9e-9 644342.28e-9 525755.35e-9 -5696.02e-9 139379.2e-9 18741.43e-9"
                  />
                  <joint
                    name="left_leg.ankle_roll"
                    axis="1 0 0"
                    range="-22.79 44.06"
                    limited="true"
                  />

                  <site name="left_sole" pos="0 0 -0.04519" />

                  <site
                    name="force_sensitive_resistors.left.rear_right"
                    pos="-0.02 0.03 -0.04519"
                    size="0.04 0.03 0.005"
                    type="box"
                    rgba="1 0 0 0.3"
                    group="3"
                  />
                  <site
                    name="force_sensitive_resistors.left.rear_left"
                    pos="-0.02 -0.023 -0.04519"
                    size="0.04 0.023 0.005"
                    type="box"
                    rgba="1 0 0 0.3"
                    group="3"
                  />
                  <site
                    name="force_sensitive_resistors.left.front_right"
                    pos="0.065 0.03 -0.04519"
                    size="0.045 0.03 0.005"
                    type="box"
                    rgba="1 0 0 0.3"
                    group="3"
                  />
                  <site
                    name="force_sensitive_resistors.left.front_left"
                    pos="0.065 -0.023 -0.04519"
                    size="0.045 0.023 0.005"
                    type="box"
                    rgba="1 0 0 0.3"
                    group="3"
                  />
                </body>
              </body>
            </body>
          </body>
        </body>
      </body>

      <body name="right_hip_1" pos="0 -0.05 -0.085">
        <geom
          type="mesh"
          material="NaoMat_Structure"
          mesh="naoRHipYawPitch_0"
        />
        <geom type="mesh" material="NaoMat_MainSkin" mesh="naoRHipYawPitch_1" />

        <inertial
          pos="-0.00781 0.01114 0.02661"
          mass="0.06981"
          fullinertia="89971.87e-9 105526.06e-9 66887.37e-9 5002.25e-9 12735.31e-9 -27700.88e-9"
        />
        <joint
          name="right_leg.hip_yaw_pitch"
          axis="0 1 1"
          range="-65.62 42.44"
          limited="true"
        />

        <body name="right_hip_2" pos="0 0 0">
          <geom type="mesh" material="NaoMat_Structure" mesh="naoRHipRoll_0" />

          <inertial
            pos="-0.01549 -0.00029 -0.00515"
            mass="0.14053"
            fullinertia="27586.44e-9 98269.99e-9 88103.38e-9 -19.16e-9 -4108.11e-9 2.52e-9"
          />
          <joint
            name="right_leg.hip_roll"
            axis="1 0 0"
            range="-45.29 21.74"
            limited="true"
          />

          <body name="right_thigh" pos="0 0 0">
            <geom
              type="mesh"
              material="NaoMat_Structure"
              mesh="naoRHipPitch_0"
            />
            <geom
              type="mesh"
              material="NaoMat_MainSkin"
              mesh="naoRHipPitch_1"
            />

            <inertial
              pos="0.00138 -0.00221 -0.05373"
              mass="0.38968"
              fullinertia="1637482.24e-9 1592213.99e-9 303978.89e-9 -839.27e-9 85887.18e-9 -39180.38e-9"
            />
            <joint
              name="right_leg.hip_pitch"
              axis="0 1 0"
              range="-88 27.73"
              limited="true"
            />

            <body name="right_tibia" pos="0 0 -0.1">
              <geom
                type="mesh"
                material="NaoMat_MainSkin"
                mesh="naoRKneePitchV6_0"
              />
              <geom
                type="mesh"
                material="NaoMat_SecondarySkin_pantone445C"
                mesh="naoRKneePitchV6_1"
              />
              <geom
                type="mesh"
                material="NaoMat_Structure"
                mesh="naoRKneePitchV6_2"
              />

              <inertial
                pos="0.00453 -0.00225 -0.04936"
                mass="0.30142"
                fullinertia="1182829.03e-9 1128278.75e-9 191453.09e-9 -896.13e-9 27999.52e-9 -38478.73e-9"
              />
              <joint
                name="right_leg.knee_pitch"
                axis="0 1 0"
                range="-5.9 121.47"
                limited="true"
              />

              <body name="right_ankle" pos="0 0 -0.1029">
                <geom
                  type="mesh"
                  material="NaoMat_Structure"
                  mesh="naoRAnklePitch_0"
                />

                <inertial
                  pos="0.00045 -0.00029 0.00685"
                  mass="0.13416"
                  fullinertia="38508.11e-9 74310.79e-9 54913.15e-9 64.34e-9 3874.68e-9 -4.6e-9"
                />
                <joint
                  name="right_leg.ankle_pitch"
                  axis="0 1 0"
                  range="-67.97 53.4"
                  limited="true"
                />

                <body name="right_foot">
                  <geom
                    type="mesh"
                    material="NaoMat_MainSkin"
                    mesh="naoRAnkleRollV6_0"
                  />
                  <geom
                    type="mesh"
                    material="NaoMat_SecondarySkin_pantone445C"
                    mesh="naoRAnkleRollV6_1"
                  />
                  <geom
                    type="mesh"
                    material="NaoMat_Structure"
                    mesh="naoRAnkleRollV6_2"
                  />
                  <geom
                    type="mesh"
                    material="NaoMat_MainSkin"
                    mesh="naoRAnkleRollV6_3"
                  />

                  <site name="right_sole" pos="0 0 -0.04519" />

                  <inertial
                    pos="0.02542 -0.0033 -0.03239"
                    mass="0.17184"
                    fullinertia="269303.1e-9 643474.47e-9 525034.16e-9 5874.62e-9 139133.06e-9 -18848.77e-9"
                  />
                  <joint
                    name="right_leg.ankle_roll"
                    axis="1 0 0"
                    range="-44.06 22.8"
                    limited="true"
                  />

                  <site
                    name="force_sensitive_resistors.right.rear_right"
                    pos="-0.02 -0.03 -0.04519"
                    size="0.04 0.03 0.005"
                    type="box"
                    rgba="1 0 0 0.3"
                    group="3"
                  />
                  <site
                    name="force_sensitive_resistors.right.rear_left"
                    pos="-0.02 0.023 -0.04519"
                    size="0.04 0.023 0.005"
                    type="box"
                    rgba="1 0 0 0.3"
                    group="3"
                  />
                  <site
                    name="force_sensitive_resistors.right.front_right"
                    pos="0.065 -0.03 -0.04519"
                    size="0.045 0.03 0.005"
                    type="box"
                    rgba="1 0 0 0.3"
                    group="3"
                  />
                  <site
                    name="force_sensitive_resistors.right.front_left"
                    pos="0.065 0.023 -0.04519"
                    size="0.045 0.023 0.005"
                    type="box"
                    rgba="1 0 0 0.3"
                    group="3"
                  />
                </body>
              </body>
            </body>
          </body>
        </body>
      </body>

      <body name="left_shoulder" pos="0 0.098 0.1">
        <geom
          type="mesh"
          material="NaoMat_MainSkin"
          mesh="naoLShoulderPitch_0"
        />

        <inertial
          pos="-0.00165 -0.02663 0.00014"
          mass="0.09304"
          fullinertia="84284.28e-9 14155.63e-9 86419.46e-9 -2028.02e-9 23.39e-9 -19.48e-9"
        />
        <joint
          name="left_arm.shoulder_pitch"
          axis="0 1 0"
          range="-119.5 119.5"
          limited="true"
        />

        <body name="left_upper_arm" pos="0 0 0">
          <geom
            type="mesh"
            material="NaoMat_SecondarySkin_pantone445C"
            mesh="naoLShoulderRollV6_0"
          />
          <geom
            type="mesh"
            material="NaoMat_Structure"
            mesh="naoLShoulderRollV6_1"
          />
          <geom
            type="mesh"
            material="NaoMat_MainSkin"
            mesh="naoLShoulderRollV6_2"
          />

          <inertial
            pos="0.02455 0.00563 0.0033"
            mass="0.15777"
            fullinertia="93900.1e-9 371518.33e-9 341901.19e-9 -47144.85e-9 -26994.73e-9 -2459.82e-9"
          />
          <joint
            name="left_arm.shoulder_roll"
            axis="0 0 1"
            range="-18 76"
            limited="true"
          />

          <body name="left_elbow" pos="0.105 0.015 0">
            <inertial
              pos="-0.02744 0 -0.00014"
              mass="0.06483"
              fullinertia="5597.15e-9 75433.15e-9 76443.38e-9 4.39e-9 43.19e-9 -1.84e-9"
            />
            <joint
              name="left_arm.elbow_yaw"
              axis="1 0 0"
              range="-119.5 119.5"
              limited="true"
            />

            <body name="left_lower_arm" pos="0 0 0">
              <geom
                type="mesh"
                material="NaoMat_MainSkin"
                mesh="naoLElbowRoll_0"
              />

              <inertial
                pos="0.02556 0.00281 0.00076"
                mass="0.07761"
                fullinertia="25332.28e-9 89132.16e-9 87287.28e-9 -2342.89e-9 74.59e-9 -26.56e-9"
              />
              <joint
                name="left_arm.elbow_roll"
                axis="0 0 1"
                range="-88.5 -2"
                limited="true"
              />

              <body name="left_wrist" pos=".05595 0 0">
                <geom
                  type="mesh"
                  material="NaoMat_MainSkin"
                  mesh="naoWristYawV6_0"
                />
                <geom
                  type="mesh"
                  material="NaoMat_SecondarySkin_pantone445C"
                  mesh="naoWristYawV6_1"
                />
                <geom
                  type="mesh"
                  material="NaoMat_Structure"
                  mesh="naoWristYawV6_2"
                />

                <inertial
                  pos="0.03434 -0.00088 0.00308"
                  mass="0.18533"
                  fullinertia="70549.38e-9 356061.81e-9 351919.25e-9 5716.67e-9 -22474.41e-9 3177.77e-9"
                />
                <joint
                  name="left_arm.wrist_yaw"
                  axis="1 0 0"
                  range="-104.5 104.5"
                  limited="true"
                />
              </body>
            </body>
          </body>
        </body>
      </body>

      <body name="right_shoulder" pos="0 -0.098 0.1">
        <geom
          type="mesh"
          material="NaoMat_MainSkin"
          mesh="naoRShoulderPitch_0"
        />

        <inertial
          pos="-0.00165 0.02663 0.00014"
          mass="0.09304"
          fullinertia="84284.28e-9 14155.62e-9 86419.46e-9 2028.02e-9 23.37e-9 19.96e-9"
        />
        <joint
          name="right_arm.shoulder_pitch"
          axis="0 1 0"
          range="-119.5 119.5"
          limited="true"
        />

        <body name="right_upper_arm" pos="0 0 0">
          <geom
            type="mesh"
            material="NaoMat_SecondarySkin_pantone445C"
            mesh="naoRShoulderRollV6_0"
          />
          <geom
            type="mesh"
            material="NaoMat_Structure"
            mesh="naoRShoulderRollV6_1"
          />
          <geom
            type="mesh"
            material="NaoMat_MainSkin"
            mesh="naoRShoulderRollV6_2"
          />

          <inertial
            pos="0.02455 -0.00563 0.0033"
            mass="0.15777"
            fullinertia="110119.78e-9 367576.65e-9 354618.19e-9 76690.99e-9 -26046.05e-9 12098.23e-9"
          />
          <joint
            name="right_arm.shoulder_roll"
            axis="0 0 1"
            range="-76 18"
            limited="true"
          />

          <body name="right_elbow" pos="0.105 -0.015 0">
            <inertial
              pos="-0.02744 0 -0.00014"
              mass="0.06483"
              fullinertia="5597.15e-9 75433.15e-9 76443.38e-9 4.39e-9 43.19e-9 -1.84e-9"
            />
            <joint
              name="right_arm.elbow_yaw"
              axis="1 0 0"
              range="-119.5 119.5"
              limited="true"
            />

            <body name="right_lower_arm" pos="0 0 0">
              <geom
                type="mesh"
                material="NaoMat_MainSkin"
                mesh="naoRElbowRoll_0"
              />

              <inertial
                pos="0.02556 -0.00281 0.00076"
                mass="0.07761"
                fullinertia="25390.7e-9 89220.44e-9 87248.38e-9 2332.25e-9 -601.17e-9 26.93e-9"
              />
              <joint
                name="right_arm.elbow_roll"
                axis="0 0 1"
                range="2 88.5"
                limited="true"
              />

              <body name="right_wrist" pos=".05595 0 0">
                <geom
                  type="mesh"
                  material="NaoMat_MainSkin"
                  mesh="naoWristYawV6_0"
                />
                <geom
                  type="mesh"
                  material="NaoMat_SecondarySkin_pantone445C"
                  mesh="naoWristYawV6_1"
                />
                <geom
                  type="mesh"
                  material="NaoMat_Structure"
                  mesh="naoWristYawV6_2"
                />

                <inertial
                  pos="0.03434 0.00088 0.00308"
                  mass="0.18533"
                  fullinertia="70549.29e-9 356061.88e-9 351919.26e-9 5716.66e-9 -22474.34e-9 3177.77e-9"
                />
                <joint
                  name="right_arm.wrist_yaw"
                  axis="1 0 0"
                  range="-104.5 104.5"
                  limited="true"
                />
              </body>
            </body>
          </body>
        </body>
      </body>
    </body>
  </worldbody>

  <contact>
    <exclude body1="Nao" body2="neck" />
    <exclude body1="Nao" body2="head" />
    <exclude body1="neck" body2="head" />
    <exclude body1="Nao" body2="left_hip_1" />
    <exclude body1="Nao" body2="left_hip_2" />
    <exclude body1="Nao" body2="left_thigh" />
    <exclude body1="Nao" body2="right_hip_1" />
    <exclude body1="Nao" body2="right_hip_2" />
    <exclude body1="Nao" body2="right_thigh" />
    <exclude body1="left_hip_1" body2="left_hip_2" />
    <exclude body1="left_hip_1" body2="left_thigh" />
    <exclude body1="left_hip_2" body2="left_thigh" />
    <exclude body1="left_thigh" body2="left_tibia" />
    <exclude body1="left_tibia" body2="left_ankle" />
    <exclude body1="left_tibia" body2="left_foot" />
    <exclude body1="left_ankle" body2="left_foot" />
    <exclude body1="right_hip_1" body2="right_hip_2" />
    <exclude body1="right_hip_1" body2="right_thigh" />
    <exclude body1="right_hip_2" body2="right_thigh" />
    <exclude body1="right_thigh" body2="right_tibia" />
    <exclude body1="right_tibia" body2="right_ankle" />
    <exclude body1="right_tibia" body2="right_foot" />
    <exclude body1="right_ankle" body2="right_foot" />
    <exclude body1="Nao" body2="left_shoulder" />
    <exclude body1="Nao" body2="left_upper_arm" />
    <exclude body1="Nao" body2="left_elbow" />
    <exclude body1="left_shoulder" body2="left_upper_arm" />
    <exclude body1="left_shoulder" body2="left_elbow" />
    <exclude body1="left_shoulder" body2="left_lower_arm" />
    <exclude body1="left_shoulder" body2="left_wrist" />
    <exclude body1="left_upper_arm" body2="left_elbow" />
    <exclude body1="left_upper_arm" body2="left_lower_arm" />
    <exclude body1="left_upper_arm" body2="left_wrist" />
    <exclude body1="left_elbow" body2="left_lower_arm" />
    <exclude body1="left_elbow" body2="left_wrist" />
    <exclude body1="left_lower_arm" body2="left_wrist" />
    <exclude body1="Nao" body2="right_shoulder" />
    <exclude body1="Nao" body2="right_upper_arm" />
    <exclude body1="Nao" body2="right_elbow" />
    <exclude body1="right_shoulder" body2="right_upper_arm" />
    <exclude body1="right_shoulder" body2="right_elbow" />
    <exclude body1="right_shoulder" body2="right_lower_arm" />
    <exclude body1="right_shoulder" body2="right_wrist" />
    <exclude body1="right_upper_arm" body2="right_elbow" />
    <exclude body1="right_upper_arm" body2="right_lower_arm" />
    <exclude body1="right_upper_arm" body2="right_wrist" />
    <exclude body1="right_elbow" body2="right_lower_arm" />
    <exclude body1="right_elbow" body2="right_wrist" />
    <exclude body1="right_lower_arm" body2="right_wrist" />
  </contact>

  <equality>
    <joint
      joint1="left_leg.hip_yaw_pitch"
      joint2="right_leg.hip_yaw_pitch"
      polycoef="0 1 0 0 0"
    />
  </equality>

  <actuator>
    <position name="head.yaw" joint="head.yaw" ctrlrange="-2.0857 2.0857" />
    <position name="head.pitch" joint="head.pitch" ctrlrange="-0.672 0.5149" />
    <position
      name="left_leg.hip_yaw_pitch"
      joint="left_leg.hip_yaw_pitch"
      ctrlrange="-1.145303 0.74081"
    />
    <position
      name="left_leg.hip_roll"
      joint="left_leg.hip_roll"
      ctrlrange="-0.379472 0.790477"
    />
    <position
      name="left_leg.hip_pitch"
      joint="left_leg.hip_pitch"
      ctrlrange="-1.535889 0.484090"
    />
    <position
      name="left_leg.knee_pitch"
      joint="left_leg.knee_pitch"
      ctrlrange="-0.092346 2.112528"
    />
    <position
      name="left_leg.ankle_pitch"
      joint="left_leg.ankle_pitch"
      ctrlrange="-1.189516 0.922747"
    />
    <position
      name="left_leg.ankle_roll"
      joint="left_leg.ankle_roll"
      ctrlrange="-0.397880  0.769001"
    />
    <!-- <position name="right_leg.hip_yaw_pitch" joint="right_leg.hip_yaw_pitch"
    ctrlrange="-1.145303 0.740810"/> -->
    <position
      name="right_leg.hip_roll"
      joint="right_leg.hip_roll"
      ctrlrange="-0.790477 0.379472"
    />
    <position
      name="right_leg.hip_pitch"
      joint="right_leg.hip_pitch"
      ctrlrange="-1.535889 0.48409"
    />
    <position
      name="right_leg.knee_pitch"
      joint="right_leg.knee_pitch"
      ctrlrange="-0.103083 2.120198"
    />
    <position
      name="right_leg.ankle_pitch"
      joint="right_leg.ankle_pitch"
      ctrlrange="-1.186448 0.932056"
    />
    <position
      name="right_leg.ankle_roll"
      joint="right_leg.ankle_roll"
      ctrlrange="-0.768992 0.397935"
    />
    <position
      name="left_arm.shoulder_pitch"
      joint="left_arm.shoulder_pitch"
      ctrlrange="-2.0857 2.0857"
    />
    <position
      name="left_arm.shoulder_roll"
      joint="left_arm.shoulder_roll"
      ctrlrange="-0.3142 1.3265"
    />
    <position
      name="left_arm.elbow_yaw"
      joint="left_arm.elbow_yaw"
      ctrlrange="-2.0857 2.0857"
    />
    <position
      name="left_arm.elbow_roll"
      joint="left_arm.elbow_roll"
      ctrlrange="-1.5446 -0.0349"
    />
    <position
      name="left_arm.wrist_yaw"
      joint="left_arm.wrist_yaw"
      ctrlrange="-1.8238 1.8238"
    />
    <position
      name="right_arm.shoulder_pitch"
      joint="right_arm.shoulder_pitch"
      ctrlrange="-2.0857 2.0857"
    />
    <position
      name="right_arm.shoulder_roll"
      joint="right_arm.shoulder_roll"
      ctrlrange="-1.3265 0.3142"
    />
    <position
      name="right_arm.elbow_yaw"
      joint="right_arm.elbow_yaw"
      ctrlrange="-2.0857 2.0857"
    />
    <position
      name="right_arm.elbow_roll"
      joint="right_arm.elbow_roll"
      ctrlrange="0.0349 1.5446"
    />
    <position
      name="right_arm.wrist_yaw"
      joint="right_arm.wrist_yaw"
      ctrlrange="-1.8238 1.8238"
    />
  </actuator>

  <sensor>
    <accelerometer name="accelerometer" site="inertial_measurement_unit" />
    <gyro name="gyroscope" site="inertial_measurement_unit" />
    <jointpos name="head.yaw" joint="head.yaw" />
    <jointpos name="head.pitch" joint="head.pitch" />
    <jointpos name="left_leg.hip_yaw_pitch" joint="left_leg.hip_yaw_pitch" />
    <jointpos name="left_leg.hip_roll" joint="left_leg.hip_roll" />
    <jointpos name="left_leg.hip_pitch" joint="left_leg.hip_pitch" />
    <jointpos name="left_leg.knee_pitch" joint="left_leg.knee_pitch" />
    <jointpos name="left_leg.ankle_pitch" joint="left_leg.ankle_pitch" />
    <jointpos name="left_leg.ankle_roll" joint="left_leg.ankle_roll" />
    <!-- <jointpos name="right_leg.hip_yaw_pitch" joint="right_leg.hip_yaw_pitch"/> -->
    <jointpos name="right_leg.hip_roll" joint="right_leg.hip_roll" />
    <jointpos name="right_leg.hip_pitch" joint="right_leg.hip_pitch" />
    <jointpos name="right_leg.knee_pitch" joint="right_leg.knee_pitch" />
    <jointpos name="right_leg.ankle_pitch" joint="right_leg.ankle_pitch" />
    <jointpos name="right_leg.ankle_roll" joint="right_leg.ankle_roll" />
    <jointpos name="left_arm.shoulder_pitch" joint="left_arm.shoulder_pitch" />
    <jointpos name="left_arm.shoulder_roll" joint="left_arm.shoulder_roll" />
    <jointpos name="left_arm.elbow_yaw" joint="left_arm.elbow_yaw" />
    <jointpos name="left_arm.elbow_roll" joint="left_arm.elbow_roll" />
    <jointpos name="left_arm.wrist_yaw" joint="left_arm.wrist_yaw" />
    <jointpos
      name="right_arm.shoulder_pitch"
      joint="right_arm.shoulder_pitch"
    />
    <jointpos name="right_arm.shoulder_roll" joint="right_arm.shoulder_roll" />
    <jointpos name="right_arm.elbow_yaw" joint="right_arm.elbow_yaw" />
    <jointpos name="right_arm.elbow_roll" joint="right_arm.elbow_roll" />
    <jointpos name="right_arm.wrist_yaw" joint="right_arm.wrist_yaw" />

    <touch
      name="force_sensitive_resistors.right.rear_left"
      site="force_sensitive_resistors.right.rear_left"
    />
    <touch
      name="force_sensitive_resistors.right.rear_right"
      site="force_sensitive_resistors.right.rear_right"
    />
    <touch
      name="force_sensitive_resistors.right.front_left"
      site="force_sensitive_resistors.right.front_left"
    />
    <touch
      name="force_sensitive_resistors.right.front_right"
      site="force_sensitive_resistors.right.front_right"
    />
    <touch
      name="force_sensitive_resistors.left.rear_right"
      site="force_sensitive_resistors.left.rear_right"
    />
    <touch
      name="force_sensitive_resistors.left.rear_left"
      site="force_sensitive_resistors.left.rear_left"
    />
    <touch
      name="force_sensitive_resistors.left.front_left"
      site="force_sensitive_resistors.left.front_left"
    />
    <touch
      name="force_sensitive_resistors.left.front_right"
      site="force_sensitive_resistors.left.front_right"
    />
  </sensor>
</mujoco>
