<mujoco model="K1">
  <compiler angle="radian" meshdir="meshes/" texturedir="textures/" />

  <default>
    <default class="colliderprimitive">
      <geom rgba="0.75294 0.75294 0.75294 0.1" />
    </default>
  </default>

  <asset>
    <texture type="skybox" builtin="gradient" rgb1="0.3 0.5 0.7" rgb2="0 0 0" width="512" height="512" />
    <texture name="texplane" type="2d" builtin="checker" rgb1=".2 .3 .4" rgb2=".1 0.15 0.2" width="512" height="512" mark="cross" markrgb=".8 .8 .8" />

    <material name="matplane" reflectance="0.3" texture="texplane" texrepeat="1 1" texuniform="true" />
    <material name="silver_plastic" rgba="0.8 0.8 0.8 1" specular="0.5" shininess="0.5" reflectance="0" />
    <material name="black_plastic" rgba="0.1 0.1 0.1 1" specular="0.3" shininess="0.5" reflectance="0" />

    <material name="black_metal_rough" rgba="0.1 0.1 0.1 1" specular="0.8" shininess="0.1" reflectance="0.1" />

    <mesh name="Trunk" file="Trunk.STL" material="silver_plastic" />
    <mesh name="Head_1" file="Head_1.STL" material="black_plastic" />
    <mesh name="Head_2" file="Head_2.STL" material="black_plastic" />
    <mesh name="Left_Arm_1" file="Left_Arm_1.STL" material="black_metal_rough" />
    <mesh name="Left_Arm_2" file="Left_Arm_2.STL" material="black_metal_rough" />
    <mesh name="Left_Arm_3" file="Left_Arm_3.STL" material="black_metal_rough" />
    <mesh name="Left_Arm_4" file="Left_Arm_4.STL" material="black_metal_rough" />
    <mesh name="Right_Arm_1" file="Right_Arm_1.STL" material="black_metal_rough" />
    <mesh name="Right_Arm_2" file="Right_Arm_2.STL" material="black_metal_rough" />
    <mesh name="Right_Arm_3" file="Right_Arm_3.STL" material="black_metal_rough" />
    <mesh name="Right_Arm_4" file="Right_Arm_4.STL" material="black_metal_rough" />
    <mesh name="Left_Hip_Pitch" file="Left_Hip_Pitch.STL" material="black_metal_rough" />
    <mesh name="Left_Hip_Roll" file="Left_Hip_Roll.STL" material="black_metal_rough" />
    <mesh name="Left_Hip_Yaw" file="Left_Hip_Yaw.STL" material="black_metal_rough" />
    <mesh name="Left_Shank" file="Left_Shank.STL" material="black_plastic" />
    <mesh name="Left_Ankle_Cross" file="Left_Ankle_Cross.STL" material="black_plastic" />
    <mesh name="Left_Foot" file="Left_Foot.STL" material="black_plastic" />
    <mesh name="Right_Hip_Pitch" file="Right_Hip_Pitch.STL" material="black_metal_rough" />
    <mesh name="Right_Hip_Roll" file="Right_Hip_Roll.STL" material="black_metal_rough" />
    <mesh name="Right_Hip_Yaw" file="Right_Hip_Yaw.STL" material="black_metal_rough" />
    <mesh name="Right_Shank" file="Right_Shank.STL" material="black_plastic" />
    <mesh name="Right_Ankle_Cross" file="Right_Ankle_Cross.STL" material="black_plastic" />
    <mesh name="Right_Foot" file="Right_Foot.STL" material="black_plastic" />
  </asset>

  <include file="ball.xml" />

  <worldbody>
    <light directional="true" diffuse=".4 .4 .4" specular="0.1 0.1 0.1" pos="0 0 5.0" dir="0 0 -1" castshadow="false" />
    <light directional="true" diffuse=".6 .6 .6" specular="0.2 0.2 0.2" pos="0 0 4" dir="0 0 -1" />
    <geom name="ground" type="plane" pos="0 0 0" size="0 0 1" material="matplane" condim="1" />

    <geom name="static_box" type="box" size="0.2 0.2 1" pos="2 1 0" rgba="0.8 0.2 0.2 1" />
    <geom name="static_capsule" type="capsule" size="0.2 0.5" pos="-2 1 0" rgba="0.8 0.2 0.2 1" />

    <geom name="static_cylinder" type="cylinder" size="0.2 0.5" pos="-2 -1 0" rgba="0.8 0.2 0.2 1" />

    <body name="Trunk" pos="0 0 0.6">
      <site name='imu' size='0.01' pos='0.0 0.0 0.0' />
      <inertial pos="-0.0043392 -0.00065534 0.065686" quat="0.999896 -0.00411546 0.0137413 -0.00168959" mass="6.3921" diaginertia="0.0962166 0.0895166 0.0201248" />
      <joint name="world_joint" type="free" limited="false" actuatorfrclimited="false" />
      <geom type="mesh" contype="0" conaffinity="0" group="1" density="0" mesh="Trunk" />
      <geom class="colliderprimitive" size="0.06 0.09 0.1" pos="0 0 0.1" type="box" />
      <geom class="colliderprimitive" size="0.05 0.05" pos="0 0 -0.06" quat="0.707105 0.707108 0 0" type="cylinder" />
      <body name="Head_1" pos="0.0056 0 0.2149">
        <inertial pos="-0.00069503 -0.00038527 0.031688" quat="0.993827 -0.00957801 0.00894723 -0.110168" mass="0.29729" diaginertia="0.000429546 0.000420659 0.000125795" />
        <joint name="AAHead_yaw" pos="0 0 0" axis="0 0 1" range="-1 1" armature="0.002" />
        <geom type="mesh" mesh="Head_1" />
        <body name="Head_2" pos="0 0 0.033">
          <inertial pos="0.011042 -0.00092871 0.080698" quat="0.996402 -0.00118413 -0.0779414 -0.0332651" mass="0.61387" diaginertia="0.00603249 0.00577511 0.0017024" />
          <joint name="Head_pitch" pos="0 0 0" axis="0 1 0" range="-0.349 0.855" armature="0.002" />
          <geom type="mesh" mesh="Head_2" />
          <body name="camera_body" pos="0.05868 0.00002 0.09849" euler="0 -1.5707963267 0">
            <camera euler="0.0 -0.2125811028 -1.5707963267" ipd="0.064" resolution="1936 1216" name="camera" />
          </body>
        </body>
      </body>
      <body name="Left_Arm_1" pos="0 0.077 0.1845">
        <inertial pos="-0.002701 0.062383 -0.011965" quat="0.578658 0.689818 -0.347436 0.261905" mass="0.45628" diaginertia="0.00223871 0.00217107 0.000254225" />
        <joint name="ALeft_Shoulder_Pitch" pos="0 0 0" axis="0 1 0" range="-3.316 1.22" armature="0.05" />
        <geom type="mesh" contype="0" conaffinity="0" group="1" density="0" mesh="Left_Arm_1" />
        <body name="Left_Arm_2" pos="0.0025 0.068 -0.0135">
          <inertial pos="0.01729 0.018221 -4.329e-05" quat="0.413453 0.573635 -0.413453 0.573635" mass="0.084303" diaginertia="0.000113 9.5e-05 6.5e-05" />
          <joint name="Left_Shoulder_Roll" pos="0 0 0" axis="1 0 0" range="-1.74 1.57" />
          <geom type="mesh" contype="0" conaffinity="0" group="1" density="0" mesh="Left_Arm_2" />
          <geom class="colliderprimitive" size="0.035 0.034" pos="-0.007 0 0" quat="0.707105 0 0.707108 0" type="cylinder" />
          <body name="Left_Arm_3" pos="0 0.044428 0">
            <inertial pos="-0.0003979 0.072617 -0.00066218" quat="0.679502 0.689551 0.177403 -0.176989" mass="0.76208" diaginertia="0.00606947 0.00606767 0.000385851" />
            <joint name="Left_Elbow_Pitch" pos="0 0 0" axis="0 1 0" range="-2.27 2.27" armature="0.05" />
            <geom type="mesh" mesh="Left_Arm_3" />
            <body name="left_hand_link" pos="0 0.1215 0">
              <inertial pos="-0.0015751 0.084637 0.0087033" quat="0.712106 0.700961 0.0264125 -0.0293496" mass="0.16796" diaginertia="0.00205619 0.00202933 8.1482e-05" />
              <joint name="Left_Elbow_Yaw" pos="0 0 0" axis="0 0 1" range="-2.44 0" />
              <geom type="mesh" mesh="Left_Arm_4" />
            </body>
          </body>
        </body>
      </body>
      <body name="Right_Arm_1" pos="0 -0.077 0.1845">
        <inertial pos="-0.0026302 -0.06251 -0.01199" quat="0.689302 0.577958 -0.263425 0.348475" mass="0.45669" diaginertia="0.00224439 0.00217742 0.000255199" />
        <joint name="ARight_Shoulder_Pitch" pos="0 0 0" axis="0 1 0" range="-3.316 1.22" armature="0.05" />
        <geom type="mesh" contype="0" conaffinity="0" group="1" density="0" mesh="Right_Arm_1" />
        <body name="Right_Arm_2" pos="0.0025 -0.068 -0.0135">
          <inertial pos="0.017229 -0.018428 4.3784e-05" quat="0.573635 0.413453 -0.573635 0.413453" mass="0.083353" diaginertia="0.000113 9.5e-05 6.5e-05" />
          <joint name="Right_Shoulder_Roll" pos="0 0 0" axis="1 0 0" range="-1.57 1.74" />
          <geom type="mesh" contype="0" conaffinity="0" group="1" density="0" mesh="Right_Arm_2" />
          <geom class="colliderprimitive" size="0.035 0.034" pos="-0.007 0 0" quat="0.707105 0 0.707108 0" type="cylinder" />
          <body name="Right_Arm_3" pos="0 -0.044428 0">
            <inertial pos="-0.00039919 -0.072601 -0.00065629" quat="0.689551 0.679502 0.176989 -0.177403" mass="0.76234" diaginertia="0.00607047 0.00606867 0.000386851" />
            <joint name="Right_Elbow_Pitch" pos="0 0 0" axis="0 1 0" range="-2.27 2.27" armature="0.05" />
            <geom type="mesh" mesh="Right_Arm_3" />
            <body name="right_hand_link" pos="0 -0.1215 0">
              <inertial pos="-0.0015177 -0.084536 0.0086733" quat="0.700925 0.712091 0.0296562 -0.0274245" mass="0.16828" diaginertia="0.00205618 0.00203032 8.14943e-05" />
              <joint name="Right_Elbow_Yaw" pos="0 0 0" axis="0 0 1" range="0 2.44" />
              <geom type="mesh" mesh="Right_Arm_4" />
            </body>
          </body>
        </body>
      </body>
      <body name="Left_Hip_Pitch" pos="0 0.096 -0.062">
        <inertial pos="-0.010093 -0.0019934 -0.024713" quat="0.704206 -0.178798 -0.198986 0.65767" mass="0.64068" diaginertia="0.000987585 0.000880963 0.000503452" />
        <joint name="Left_Hip_Pitch" pos="0 0 0" axis="0 1 0" range="-3 2.21" />
        <geom type="mesh" contype="0" conaffinity="0" group="1" density="0" mesh="Left_Hip_Pitch" />
        <body name="Left_Hip_Roll" pos="0 0 -0.026">
          <inertial pos="0.023585 4.9e-05 -0.024996" quat="0.677218 0.203412 0.203412 0.677218" mass="0.127825" diaginertia="0.000262 0.000222694 0.000118306" />
          <joint name="Left_Hip_Roll" pos="0 0 0" axis="1 0 0" range="-0.4 1.57" />
          <geom type="mesh" contype="0" conaffinity="0" group="1" density="0" mesh="Left_Hip_Roll" />
          <geom class="colliderprimitive" size="0.036 0.047" quat="0.707105 0 0.707108 0" type="cylinder" />
          <body name="Left_Hip_Yaw" pos="0.012 0 -0.0485">
            <inertial pos="-0.0084744 -0.0040494 -0.087906" quat="0.857995 -0.00590801 -0.0582713 0.510308" mass="1.5591" diaginertia="0.0162716 0.0158564 0.00134895" />
            <joint name="Left_Hip_Yaw" pos="0 0 0" axis="0 0 1" range="-1 1" />
            <geom type="mesh" contype="0" conaffinity="0" group="1" density="0" mesh="Left_Hip_Yaw" />
            <geom class="colliderprimitive" size="0.04 0.033" pos="0 0 -0.03" type="cylinder" />
            <body name="Left_Shank" pos="-0.014 0 -0.117">
              <inertial pos="-0.00081083 0.0031459 -0.10922" quat="0.940563 -0.00388906 -0.00385774 0.339574" mass="1.48333" diaginertia="0.0237114 0.0236423 0.00123731" />
              <joint name="Left_Knee_Pitch" pos="0 0 0" axis="0 1 0" range="0 2.23" />
              <geom type="mesh" contype="0" conaffinity="0" group="1" density="0" mesh="Left_Shank" />
              <geom class="colliderprimitive" size="0.045 0.035" quat="0.707105 0.707108 0 0" type="cylinder" />
              <geom class="colliderprimitive" size="0.03 0.03 0.05" pos="0 0 -0.13" type="box" />
              <body name="Left_Ankle_Cross" pos="0.00019706 0.0002 -0.24519">
                <inertial pos="0 0 0" quat="0.5 0.5 0.5 0.5" mass="0.038836" diaginertia="4e-06 4e-06 2e-06" />
                <joint name="Left_Ankle_Pitch" pos="0 0 0" axis="0 1 0" range="-0.87 0.345" armature="0.05" />
                <geom type="mesh" contype="0" conaffinity="0" group="1" density="0" mesh="Left_Ankle_Cross" />
                <body name="left_foot_link">
                  <inertial pos="7.3589e-05 -4.1141e-06 -0.0075032" quat="0 0.674609 0 0.738175" mass="0.38305" diaginertia="0.000789779 0.000741 0.000197221" />
                  <joint name="Left_Ankle_Roll" pos="0 0 0" axis="1 0 0" range="-0.345 0.345" armature="0.05" />
                  <geom type="mesh" contype="0" conaffinity="0" group="1" density="0" mesh="Left_Foot" />
                  <geom class="colliderprimitive" type="box" pos="0.014 0 -0.008" size="0.08 0.035 0.016" />
                </body>
              </body>
            </body>
          </body>
        </body>
      </body>
      <body name="Right_Hip_Pitch" pos="0 -0.096 -0.062">
        <inertial pos="-0.010065 0.0020086 -0.024739" quat="0.656712 -0.199052 -0.176963 0.705544" mass="0.6413" diaginertia="0.000988671 0.000880749 0.00050458" />
        <joint name="Right_Hip_Pitch" pos="0 0 0" axis="0 1 0" range="-3 2.21" />
        <geom type="mesh" contype="0" conaffinity="0" group="1" density="0" mesh="Right_Hip_Pitch" />
        <body name="Right_Hip_Roll" pos="0 0 -0.026">
          <inertial pos="0.023585 4.9e-05 -0.024996" quat="0.677218 0.203412 0.203412 0.677218" mass="0.127825" diaginertia="0.000262 0.000222694 0.000118306" />
          <joint name="Right_Hip_Roll" pos="0 0 0" axis="1 0 0" range="-1.57 0.4" />
          <geom type="mesh" contype="0" conaffinity="0" group="1" density="0" mesh="Right_Hip_Roll" />
          <geom class="colliderprimitive" size="0.036 0.047" quat="0.707105 0 0.707108 0" type="cylinder" />
          <body name="Right_Hip_Yaw" pos="0.012 0 -0.0485">
            <inertial pos="-0.008475 0.0040392 -0.087906" quat="0.510308 -0.0582713 -0.00590801 0.857995" mass="1.5592" diaginertia="0.0162716 0.0158564 0.00134895" />
            <joint name="Right_Hip_Yaw" pos="0 0 0" axis="0 0 1" range="-1 1" />
            <geom type="mesh" contype="0" conaffinity="0" group="1" density="0" mesh="Right_Hip_Yaw" />
            <geom class="colliderprimitive" size="0.04 0.033" pos="0 0 -0.03" type="cylinder" />
            <body name="Right_Shank" pos="-0.014 0 -0.117">
              <inertial pos="-0.000805 -0.003146 -0.109215" quat="0.940537 0.00388176 -0.00383651 -0.339646" mass="1.48334" diaginertia="0.0237114 0.0236423 0.00123733" />
              <joint name="Right_Knee_Pitch" pos="0 0 0" axis="0 1 0" range="0 2.23" />
              <geom type="mesh" contype="0" conaffinity="0" group="1" density="0" mesh="Right_Shank" />
              <geom class="colliderprimitive" size="0.045 0.035" quat="0.707105 0.707108 0 0" type="cylinder" />
              <geom class="colliderprimitive" size="0.03 0.03 0.05" pos="0 0 -0.13" type="box" />
              <body name="Right_Ankle_Cross" pos="0.00019706 -0.0002 -0.24519">
                <inertial pos="0 0 0" quat="0.5 0.5 0.5 0.5" mass="0.038836" diaginertia="4e-06 4e-06 2e-06" />
                <joint name="Right_Ankle_Pitch" pos="0 0 0" axis="0 1 0" range="-0.87 0.345" armature="0.05" />
                <geom type="mesh" contype="0" conaffinity="0" group="1" density="0" mesh="Right_Ankle_Cross" />
                <body name="right_foot_link">
                  <inertial pos="-0.000178 -2e-06 -0.007291" quat="0 0.674109 0 0.738632" mass="0.38637" diaginertia="0.000794943 0.000745 0.000200057" />
                  <joint name="Right_Ankle_Roll" pos="0 0 0" axis="1 0 0" range="-0.345 0.345" armature="0.05" />
                  <geom type="mesh" contype="0" conaffinity="0" group="1" density="0" mesh="Right_Foot" />
                  <geom class="colliderprimitive" type="box" pos="0.014 0 -0.008" size="0.08 0.035 0.016" />
                </body>
              </body>
            </body>
          </body>
        </body>
      </body>
    </body>
  </worldbody>
  <actuator>
    <motor name="AAHead_yaw" joint="AAHead_yaw" ctrllimited="true" ctrlrange="-7.0 7.0" />
    <motor name="Head_pitch" joint="Head_pitch" ctrllimited="true" ctrlrange="-7.0 7.0" />
    <motor name="ALeft_Shoulder_Pitch" joint="ALeft_Shoulder_Pitch" ctrllimited="true" ctrlrange="-10.0 10.0" />
    <motor name="Left_Shoulder_Roll" joint="Left_Shoulder_Roll" ctrllimited="true" ctrlrange="-10.0 10.0" />
    <motor name="Left_Elbow_Pitch" joint="Left_Elbow_Pitch" ctrllimited="true" ctrlrange="-10.0 10.0" />
    <motor name="Left_Elbow_Yaw" joint="Left_Elbow_Yaw" ctrllimited="true" ctrlrange="-10.0 10.0" />
    <motor name="ARight_Shoulder_Pitch" joint="ARight_Shoulder_Pitch" ctrllimited="true" ctrlrange="-10.0 10.0" />
    <motor name="Right_Shoulder_Roll" joint="Right_Shoulder_Roll" ctrllimited="true" ctrlrange="-10.0 10.0" />
    <motor name="Right_Elbow_Pitch" joint="Right_Elbow_Pitch" ctrllimited="true" ctrlrange="-10.0 10.0" />
    <motor name="Right_Elbow_Yaw" joint="Right_Elbow_Yaw" ctrllimited="true" ctrlrange="-10.0 10.0" />
    <motor name="Left_Hip_Pitch" joint="Left_Hip_Pitch" ctrllimited="true" ctrlrange="-45.0 45.0" />
    <motor name="Left_Hip_Roll" joint="Left_Hip_Roll" ctrllimited="true" ctrlrange="-30.0 30.0" />
    <motor name="Left_Hip_Yaw" joint="Left_Hip_Yaw" ctrllimited="true" ctrlrange="-30.0 30.0" />
    <motor name="Left_Knee_Pitch" joint="Left_Knee_Pitch" ctrllimited="true" ctrlrange="-45.0 45.0" />
    <motor name="Left_Ankle_Pitch" joint="Left_Ankle_Pitch" ctrllimited="true" ctrlrange="-20.0 20.0" />
    <motor name="Left_Ankle_Roll" joint="Left_Ankle_Roll" ctrllimited="true" ctrlrange="-20.0 20.0" />
    <motor name="Right_Hip_Pitch" joint="Right_Hip_Pitch" ctrllimited="true" ctrlrange="-45.0 45.0" />
    <motor name="Right_Hip_Roll" joint="Right_Hip_Roll" ctrllimited="true" ctrlrange="-30.0 30.0" />
    <motor name="Right_Hip_Yaw" joint="Right_Hip_Yaw" ctrllimited="true" ctrlrange="-30.0 30.0" />
    <motor name="Right_Knee_Pitch" joint="Right_Knee_Pitch" ctrllimited="true" ctrlrange="-45.0 45.0" />
    <motor name="Right_Ankle_Pitch" joint="Right_Ankle_Pitch" ctrllimited="true" ctrlrange="-20.0 20.0" />
    <motor name="Right_Ankle_Roll" joint="Right_Ankle_Roll" ctrllimited="true" ctrlrange="-20.0 20.0" />
  </actuator>
  <sensor>
    <framequat name="orientation" objtype="site" noise="0.001" objname="imu" />
    <gyro name="angular-velocity" site="imu" noise="0.005" />
    <accelerometer name="accelerometer" site="imu" noise="0.005" />
  </sensor>
</mujoco>
