<?xml version="1.0" encoding="utf-8"?>
<!-- This URDF was automatically created by SolidWorks to URDF Exporter! Originally created by Stephen Brawner (brawner@gmail.com) 
     Commit Version: 1.6.0-4-g7f85cfe  Build Version: 1.6.7995.38578
     For more information, please see http://wiki.ros.org/sw_urdf_exporter -->
<robot
  name="K1">

  <!--mujoco>
    <compiler meshdir="meshes/" balanceinertia="true" discardvisual="false"/>
  </mujoco-->
  <!-- for convert to mujoco -->
  <!--link name="world"/>
  <joint name="world_joint" type="floating">
    <origin xyz="0 0 0"/>
    <parent link="world"/>
    <child link="Trunk"/>
  </joint-->

  <link
    name="Trunk">
    <inertial>
      <origin
        xyz="-0.0043392 -0.00065534 0.065686"
        rpy="0 0 0" />
      <mass
        value="6.3921" />
      <inertia
        ixx="0.096159"
        ixy="-0.000039"
        ixz="-0.002091"
        iyy="0.089512"
        iyz="-0.000567"
        izz="0.020187" />
    </inertial>
    <visual>
      <origin
        xyz="0 0 0"
        rpy="0 0 0" />
      <geometry>
        <mesh
          filename="meshes/Trunk.STL" />
      </geometry>
      <material
        name="">
        <color
          rgba="0.75294 0.75294 0.75294 1" />
      </material>
    </visual>
    <collision>
      <origin
        xyz="0 0 0.1"
        rpy="0 0 0" />
      <geometry>
        <box size="0.12 0.18 0.2" />
      </geometry>
    </collision>
    <collision>
      <origin
        xyz="0 0 -0.06"
        rpy="1.5708 0 0" />
      <geometry>
        <cylinder radius="0.05" length="0.1" />
      </geometry>
    </collision>
  </link>
  <link
    name="Head_1">
    <inertial>
      <origin
        xyz="-0.00069503 -0.00038527 0.031688"
        rpy="0 0 0" />
      <mass
        value="0.29729" />
      <inertia
        ixx="0.000429"
        ixy="-0.000002"
        ixz="-0.000006"
        iyy="0.000421"
        iyz="-0.000005"
        izz="0.000126" />
    </inertial>
    <visual>
      <origin
        xyz="0 0 0"
        rpy="0 0 0" />
      <geometry>
        <mesh
          filename="meshes/Head_1.STL" />
      </geometry>
      <material
        name="">
        <color
          rgba="0.75294 0.75294 0.75294 1" />
      </material>
    </visual>
    <collision>
      <origin
        xyz="0 0 0"
        rpy="0 0 0" />
      <geometry>
        <mesh
          filename="meshes/Head_1.STL" />
      </geometry>
    </collision>
  </link>
  <joint
    name="AAHead_yaw"
    type="revolute">
    <origin
      xyz="0.0056 0 0.2149"
      rpy="0 0 0" />
    <parent
      link="Trunk" />
    <child
      link="Head_1" />
    <axis
      xyz="0 0 1" />
    <limit
      lower="-1."
      upper="1."
      effort="7"
      velocity="18"
    />
  </joint>
  <link
    name="Head_2">
    <inertial>
      <origin
        xyz="0.006640 0.000764 0.072506"
        rpy="0 0 0" />
      <mass
        value="0.781574" />
      <inertia
        ixx="0.006825"
        ixy="-0.000002"
        ixz="0.000481"
        iyy="0.005840"
        iyz="0.000048"
        izz="0.002900" />
    </inertial>
    <visual>
      <origin
        xyz="0 0 0"
        rpy="0 0 0" />
      <geometry>
        <mesh
          filename="meshes/Head_2_ZED.STL" />
      </geometry>
      <material
        name="">
        <color
          rgba="0.75294 0.75294 0.75294 1" />
      </material>
    </visual>
    <collision>
      <origin
        xyz="0 0 0"
        rpy="0 0 0" />
      <geometry>
        <mesh
          filename="meshes/Head_2.STL" />
      </geometry>
    </collision>
  </link>
  <joint
    name="Head_pitch"
    type="revolute">
    <origin
      xyz="0 0 0.033"
      rpy="0 0 0" />
    <parent
      link="Head_1" />
    <child
      link="Head_2" />
    <axis
      xyz="0 1 0" />
    <limit
      lower="-0.349"
      upper="0.855"
      effort="7"
      velocity="18"
    />
  </joint>
  <link
    name="Left_Arm_1">
    <inertial>
      <origin
        xyz="-0.002701 0.062383 -0.011965"
        rpy="0 0 0" />
      <mass
        value="0.45628" />
      <inertia
        ixx="0.002194"
        ixy="-0.000084"
        ixz="0.000017"
        iyy="0.000331"
        iyz="-0.000372"
        izz="0.002139" />
    </inertial>
    <visual>
      <origin
        xyz="0 0 0"
        rpy="0 0 0" />
      <geometry>
        <mesh
          filename="meshes/Left_Arm_1.STL" />
      </geometry>
      <material
        name="">
        <color
          rgba="0.75294 0.75294 0.75294 1" />
      </material>
    </visual>
  </link>
  <joint
    name="ALeft_Shoulder_Pitch"
    type="revolute">
    <origin
      xyz="0 0.077 0.1845"
      rpy="0 0 0" />
    <parent
      link="Trunk" />
    <child
      link="Left_Arm_1" />
    <axis
      xyz="0 1 0" />
    <limit
      lower="-3.316"
      upper="1.22"
      effort="10"
      velocity="18"
    />
  </joint>
  <link
    name="Left_Arm_2">
    <inertial>
      <origin
        xyz="0.01729 0.018221 -4.329E-05"
        rpy="0 0 0" />
      <mass
        value="0.084303" />
      <inertia
        ixx="0.000092"
        ixy="0.000009"
        ixz="0.000000"
        iyy="0.000068"
        iyz="0.000000"
        izz="0.000113" />
    </inertial>
    <visual>
      <origin
        xyz="0 0 0"
        rpy="0 0 0" />
      <geometry>
        <mesh
          filename="meshes/Left_Arm_2.STL" />
      </geometry>
      <material
        name="">
        <color
          rgba="0.75294 0.75294 0.75294 1" />
      </material>
    </visual>
    <collision>
      <origin
        xyz="-0.007 0 0"
        rpy="0 1.5708 0" />
      <geometry>
        <cylinder radius="0.035" length="0.068" />
      </geometry>
    </collision>
  </link>
  <joint
    name="Left_Shoulder_Roll"
    type="revolute">
    <origin
      xyz="0.0025 0.068 -0.0135"
      rpy="0 0 0" />
    <parent
      link="Left_Arm_1" />
    <child
      link="Left_Arm_2" />
    <axis
      xyz="1 0 0" />
    <limit
      lower="-1.74"
      upper="1.57"
      effort="10"
      velocity="18"
    />
  </joint>
  <link
    name="Left_Arm_3">
    <inertial>
      <origin
        xyz="-0.0003979 0.072617 -0.00066218"
        rpy="0 0 0" />
      <mass
        value="0.76208" />
      <inertia
        ixx="0.006069"
        ixy="-0.000017"
        ixz=" -0.000001"
        iyy="0.000387"
        iyz="-0.000079"
        izz="0.006067" />
    </inertial>
    <visual>
      <origin
        xyz="0 0 0"
        rpy="0 0 0" />
      <geometry>
        <mesh
          filename="meshes/Left_Arm_3.STL" />
      </geometry>
      <material
        name="">
        <color
          rgba="0.75294 0.75294 0.75294 1" />
      </material>
    </visual>
    <collision>
      <origin
        xyz="0 0 0"
        rpy="0 0 0" />
      <geometry>
        <mesh
          filename="meshes/Left_Arm_3.STL" />
      </geometry>
    </collision>
  </link>
  <joint
    name="Left_Elbow_Pitch"
    type="revolute">
    <origin
      xyz="0 0.044428 0"
      rpy="0 0 0" />
    <parent
      link="Left_Arm_2" />
    <child
      link="Left_Arm_3" />
    <axis
      xyz="0 1 0" />
    <limit
      lower="-2.27"
      upper="2.27"
      effort="10"
      velocity="18"
    />
  </joint>
  <link
    name="left_hand_link">
    <inertial>
      <origin
        xyz="-0.0015751 0.084637 0.0087033"
        rpy="0 0 0" />
      <mass
        value="0.16796" />
      <inertia
        ixx="0.002056"
        ixy="-0.000007"
        ixz="-0.000002"
        iyy="0.000082"
        iyz="0.000031"
        izz="0.002029" />
    </inertial>
    <visual>
      <origin
        xyz="0 0 0"
        rpy="0 0 0" />
      <geometry>
        <mesh
          filename="meshes/Left_Arm_4.STL" />
      </geometry>
      <material
        name="">
        <color
          rgba="0.75294 0.75294 0.75294 1" />
      </material>
    </visual>
    <collision>
      <origin
        xyz="0 0 0"
        rpy="0 0 0" />
      <geometry>
        <mesh
          filename="meshes/Left_Arm_4.STL" />
      </geometry>
    </collision>
  </link>
  <joint
    name="Left_Elbow_Yaw"
    type="revolute">
    <origin
      xyz="0 0.1215 0"
      rpy="0 0 0" />
    <parent
      link="Left_Arm_3" />
    <child
      link="left_hand_link" />
    <axis
      xyz="0 0 1" />
    <limit
      lower="-2.44"
      upper="0"
      effort="10"
      velocity="18"
    />
  </joint>

  <link
    name="left_hand_end_ball">
    <inertial>
      <origin
        xyz="0 0 0"
        rpy="0 0 0" />
      <mass
        value="0.002" />
      <inertia
        ixx="1.0e-5"
        ixy="0.0"
        ixz="0.0"
        iyy="1.0e-5"
        iyz="0.0"
        izz="1.0e-5" />
    </inertial>
    <visual>
      <origin
        xyz="0 0 0"
        rpy="0 0 0" />
      <geometry>
        <sphere radius="0.025" />
      </geometry>
    </visual>
    <collision>
      <origin
        xyz="0 0 0"
        rpy="0 0 0" />
      <geometry>
        <sphere radius="0.025" />
      </geometry>
    </collision>
  </link>
  <joint
    name="Left_Hand_End_Ball"
    type="fixed">
    <origin
      xyz="0 0.203 0"
      rpy="0 0 0" />
    <parent
      link="left_hand_link" />
    <child
      link="left_hand_end_ball" />
    <axis
      xyz="0 0 1" />
    <limit
      lower="-3.14"
      upper="3.14"
      effort="0.1"
      velocity="0.1" />
  </joint>

  <link
    name="Right_Arm_1">
    <inertial>
      <origin
        xyz="-0.0026302 -0.06251 -0.01199"
        rpy="0 0 0" />
      <mass
        value="0.45669" />
      <inertia
        ixx="0.002200"
        ixy="0.000082"
        ixz="0.000017"
        iyy="0.000332"
        iyz="0.000373"
        izz="0.002145" />
    </inertial>
    <visual>
      <origin
        xyz="0 0 0"
        rpy="0 0 0" />
      <geometry>
        <mesh
          filename="meshes/Right_Arm_1.STL" />
      </geometry>
      <material
        name="">
        <color
          rgba="0.75294 0.75294 0.75294 1" />
      </material>
    </visual>
  </link>
  <joint
    name="ARight_Shoulder_Pitch"
    type="revolute">
    <origin
      xyz="0 -0.077 0.1845"
      rpy="0 0 0" />
    <parent
      link="Trunk" />
    <child
      link="Right_Arm_1" />
    <axis
      xyz="0 1 0" />
    <limit
      lower="-3.316"
      upper="1.22"
      effort="10"
      velocity="18"
    />
  </joint>
  <link
    name="Right_Arm_2">
    <inertial>
      <origin
        xyz="0.017229 -0.018428 4.3784E-05"
        rpy="0 0 0" />
      <mass
        value="0.083353" />
      <inertia
        ixx="0.000092"
        ixy="-0.000009"
        ixz="0.000000"
        iyy="0.000068"
        iyz="0.000000"
        izz="0.000113" />
    </inertial>
    <visual>
      <origin
        xyz="0 0 0"
        rpy="0 0 0" />
      <geometry>
        <mesh
          filename="meshes/Right_Arm_2.STL" />
      </geometry>
      <material
        name="">
        <color
          rgba="0.75294 0.75294 0.75294 1" />
      </material>
    </visual>
    <collision>
      <origin
        xyz="-0.007 0 0"
        rpy="0 1.5708 0" />
      <geometry>
        <cylinder radius="0.035" length="0.068" />
      </geometry>
    </collision>
  </link>
  <joint
    name="Right_Shoulder_Roll"
    type="revolute">
    <origin
      xyz="0.0025 -0.068 -0.0135"
      rpy="0 0 0" />
    <parent
      link="Right_Arm_1" />
    <child
      link="Right_Arm_2" />
    <axis
      xyz="1 0 0" />
    <limit
      lower="-1.57"
      upper="1.74"
      effort="10"
      velocity="18"
    />
  </joint>
  <link
    name="Right_Arm_3">
    <inertial>
      <origin
        xyz="-0.00039919 -0.072601 -0.00065629"
        rpy="0 0 0" />
      <mass
        value="0.76234" />
      <inertia
        ixx="0.006070"
        ixy="0.000017"
        ixz="-0.000001"
        iyy="0.000388"
        iyz="0.000079"
        izz="0.006068" />
    </inertial>
    <visual>
      <origin
        xyz="0 0 0"
        rpy="0 0 0" />
      <geometry>
        <mesh
          filename="meshes/Right_Arm_3.STL" />
      </geometry>
      <material
        name="">
        <color
          rgba="0.75294 0.75294 0.75294 1" />
      </material>
    </visual>
    <collision>
      <origin
        xyz="0 0 0"
        rpy="0 0 0" />
      <geometry>
        <mesh
          filename="meshes/Right_Arm_3.STL" />
      </geometry>
    </collision>
  </link>
  <joint
    name="Right_Elbow_Pitch"
    type="revolute">
    <origin
      xyz="0 -0.044428 0"
      rpy="0 0 0" />
    <parent
      link="Right_Arm_2" />
    <child
      link="Right_Arm_3" />
    <axis
      xyz="0 1 0" />
    <limit
      lower="-2.27"
      upper="2.27"
      effort="10"
      velocity="18"
    />
  </joint>
  <link
    name="right_hand_link">
    <inertial>
      <origin
        xyz="-0.0015177 -0.084536 0.0086733"
        rpy="0 0 0" />
      <mass
        value="0.16828" />
      <inertia
        ixx="0.002056"
        ixy="0.000005"
        ixz="-0.000002"
        iyy="0.000082"
        iyz="-0.000031"
        izz="0.002030" />
    </inertial>
    <visual>
      <origin
        xyz="0 0 0"
        rpy="0 0 0" />
      <geometry>
        <mesh
          filename="meshes/Right_Arm_4.STL" />
      </geometry>
      <material
        name="">
        <color
          rgba="0.75294 0.75294 0.75294 1" />
      </material>
    </visual>
    <collision>
      <origin
        xyz="0 0 0"
        rpy="0 0 0" />
      <geometry>
        <mesh
          filename="meshes/Right_Arm_4.STL" />
      </geometry>
    </collision>
  </link>
  <joint
    name="Right_Elbow_Yaw"
    type="revolute">
    <origin
      xyz="0 -0.1215 0"
      rpy="0 0 0" />
    <parent
      link="Right_Arm_3" />
    <child
      link="right_hand_link" />
    <axis
      xyz="0 0 1" />
    <limit
      lower="0"
      upper="2.44"
      effort="10"
      velocity="18"
    />
  </joint>

  <link
    name="right_hand_end_ball">
    <inertial>
      <origin
        xyz="0 0 0"
        rpy="0 0 0" />
      <mass
        value="0.002" />
      <inertia
        ixx="1.0e-5"
        ixy="0.0"
        ixz="0.0"
        iyy="1.0e-5"
        iyz="0.0"
        izz="1.0e-5" />
    </inertial>
    <visual>
      <origin
        xyz="0 0 0"
        rpy="0 0 0" />
      <geometry>
        <sphere radius="0.025" />
      </geometry>
    </visual>
    <collision>
      <origin
        xyz="0 0 0"
        rpy="0 0 0" />
      <geometry>
        <sphere radius="0.025" />
      </geometry>
    </collision>
  </link>
  <joint
    name="Right_Hand_End_Ball"
    type="fixed">
    <origin
      xyz="0 -0.203 0"
      rpy="0 0 0" />
    <parent
      link="right_hand_link" />
    <child
      link="right_hand_end_ball" />
    <axis
      xyz="0 0 1" />
    <limit
      lower="-3.14"
      upper="3.14"
      effort="0.1"
      velocity="0.1" />
  </joint>

  <link
    name="Left_Hip_Pitch">
    <inertial>
      <origin
        xyz="-0.010093 -0.0019934 -0.024713"
        rpy="0 0 0" />
      <mass
        value="0.64068" />
      <inertia
        ixx="0.000781"
        ixy="0.000004"
        ixz="0.000167"
        iyy="0.000987"
        iyz="0.000008"
        izz="0.000604" />
    </inertial>
    <visual>
      <origin
        xyz="0 0 0"
        rpy="0 0 0" />
      <geometry>
        <mesh
          filename="meshes/Left_Hip_Pitch.STL" />
      </geometry>
      <material
        name="">
        <color
          rgba="0.75294 0.75294 0.75294 1" />
      </material>
    </visual>
  </link>
  <joint
    name="Left_Hip_Pitch"
    type="revolute">
    <origin
      xyz="0 0.096 -0.062"
      rpy="0 0 0" />
    <parent
      link="Trunk" />
    <child
      link="Left_Hip_Pitch" />
    <axis
      xyz="0 1 0" />
    <limit
      lower="-3.0"
      upper="2.21"
      effort="45"
      velocity="18"
    />
  </joint>
  <link
    name="Left_Hip_Roll">
    <inertial>
      <origin
        xyz="0.023585 0.000049 -0.024996"
        rpy="0 0 0" />
      <mass
        value="0.127825" />
      <inertia
        ixx="0.000191"
        ixy="0.000000"
        ixz="-0.000048"
        iyy="0.000262"
        iyz="0.000000"
        izz="0.000150" />
    </inertial>
    <visual>
      <origin
        xyz="0 0 0"
        rpy="0 0 0" />
      <geometry>
        <mesh
          filename="meshes/Left_Hip_Roll.STL" />
      </geometry>
      <material
        name="">
        <color
          rgba="0.75294 0.75294 0.75294 1" />
      </material>
    </visual>
    <collision>
      <origin
        xyz="0 0 0"
        rpy="0 1.5708 0" />
      <geometry>
        <cylinder radius="0.036" length="0.094" />
      </geometry>
    </collision>
  </link>
  <joint
    name="Left_Hip_Roll"
    type="revolute">
    <origin
      xyz="0 0 -0.026"
      rpy="0 0 0" />
    <parent
      link="Left_Hip_Pitch" />
    <child
      link="Left_Hip_Roll" />
    <axis
      xyz="1 0 0" />
    <limit
      lower="-0.4"
      upper="1.57"
      effort="30"
      velocity="18"
    />
  </joint>
  <link
    name="Left_Hip_Yaw">
    <inertial>
      <origin
        xyz="-0.0084744 -0.0040494 -0.087906"
        rpy="0 0 0" />
      <mass
        value="1.5591" />
      <inertia
        ixx="0.015786"
        ixy="0.000096"
        ixz="0.001546"
        iyy="0.016140"
        iyz="0.000745"
        izz="0.001551" />
    </inertial>
    <visual>
      <origin
        xyz="0 0 0"
        rpy="0 0 0" />
      <geometry>
        <mesh
          filename="meshes/Left_Hip_Yaw.STL" />
      </geometry>
      <material
        name="">
        <color
          rgba="0.75294 0.75294 0.75294 1" />
      </material>
    </visual>
    <collision>
      <origin
        xyz="0 0 -0.03"
        rpy="0 0 0" />
      <geometry>
        <cylinder radius="0.04" length="0.066" />
      </geometry>
    </collision>
  </link>
  <joint
    name="Left_Hip_Yaw"
    type="revolute">
    <origin
      xyz="0.012 0 -0.0485"
      rpy="0 0 0" />
    <parent
      link="Left_Hip_Roll" />
    <child
      link="Left_Hip_Yaw" />
    <axis
      xyz="0 0 1" />
    <limit
      lower="-1."
      upper="1."
      effort="30"
      velocity="18"
    />
  </joint>
  <link
    name="Left_Shank">
    <inertial>
      <origin
        xyz="-0.00081083 0.0031459 -0.10922"
        rpy="0 0 0" />
      <mass
        value="1.483334" />
      <inertia
        ixx="0.023681"
        ixy="0.000035"
        ixz="0.000222"
        iyy="0.023670"
        iyz="-0.000105"
        izz="0.001240" />
    </inertial>
    <visual>
      <origin
        xyz="0 0 0"
        rpy="0 0 0" />
      <geometry>
        <mesh
          filename="meshes/Left_Shank.STL" />
      </geometry>
      <material
        name="">
        <color
          rgba="0.75294 0.75294 0.75294 1" />
      </material>
    </visual>
    <collision>
      <origin
        xyz="0 0 0"
        rpy="1.5708 0 0" />
      <geometry>
        <cylinder radius="0.045" length="0.07" />
      </geometry>
    </collision>
    <collision>
      <origin
        xyz="0 0 -0.13"
        rpy="0 0 0" />
      <geometry>
        <box size="0.06 0.06 0.10" />
      </geometry>
    </collision>
  </link>
  <joint
    name="Left_Knee_Pitch"
    type="revolute">
    <origin
      xyz="-0.014 0 -0.117"
      rpy="0 0 0" />
    <parent
      link="Left_Hip_Yaw" />
    <child
      link="Left_Shank" />
    <axis
      xyz="0 1 0" />
    <limit
      lower="0."
      upper="2.23"
      effort="45"
      velocity="18"
    />
  </joint>
  <link
    name="Left_Ankle_Cross">
    <inertial>
      <origin
        xyz="0.000000 0.000000 0.000000"
        rpy="0 0 0" />
      <mass
        value="0.038836" />
      <inertia
        ixx="0.000002"
        ixy="0.000000"
        ixz="0.000000"
        iyy="0.000004"
        iyz="0.000000"
        izz="0.000004" />
    </inertial>
    <visual>
      <origin
        xyz="0 0 0"
        rpy="0 0 0" />
      <geometry>
        <mesh
          filename="meshes/Left_Ankle_Cross.STL" />
      </geometry>
      <material
        name="">
        <color
          rgba="0.75294 0.75294 0.75294 1" />
      </material>
    </visual>
  </link>
  <joint
    name="Left_Ankle_Pitch"
    type="revolute">
    <origin
      xyz="0.00019706 0.0002 -0.24519"
      rpy="0 0 0" />
    <parent
      link="Left_Shank" />
    <child
      link="Left_Ankle_Cross" />
    <axis
      xyz="0 1 0" />
    <limit
      lower="-0.87"
      upper="0.345"
      effort="20"
      velocity="18"
    />
  </joint>
  <link
    name="left_foot_link">
    <inertial>
      <origin
        xyz="7.3589E-05 -4.1141E-06 -0.0075032"
        rpy="0 0 0" />
      <mass
        value="0.38305" />
      <inertia
        ixx="0.000202"
        ixy="0.000000"
        ixz="-0.000053"
        iyy="0.000741"
        iyz="0.000000"
        izz="0.000785" />
    </inertial>
    <visual>
      <origin
        xyz="0 0 0"
        rpy="0 0 0" />
      <geometry>
        <mesh
          filename="meshes/Left_Foot.STL" />
      </geometry>
      <material
        name="">
        <color
          rgba="0.75294 0.75294 0.75294 1" />
      </material>
    </visual>
    <collision>
      <origin
        xyz="0 0 0"
        rpy="0 0 0" />
      <geometry>
        <mesh
          filename="meshes/Left_Foot.STL" />
      </geometry>
    </collision>
  </link>
  <joint
    name="Left_Ankle_Roll"
    type="revolute">
    <origin
      xyz="0 0 0"
      rpy="0 0 0" />
    <parent
      link="Left_Ankle_Cross" />
    <child
      link="left_foot_link" />
    <axis
      xyz="1 0 0" />
    <limit
      lower="-0.345"
      upper="0.345"
      effort="20"
      velocity="18"
    />
  </joint>

  <link
    name="Right_Hip_Pitch">
    <inertial>
      <origin
        xyz="-0.010065 0.0020086 -0.024739"
        rpy="0 0 0" />
      <mass
        value="0.6413" />
      <inertia
        ixx="0.000782"
        ixy="-0.000004"
        ixz="0.000166"
        iyy="0.000988"
        iyz="-0.000009"
        izz="0.000604" />
    </inertial>
    <visual>
      <origin
        xyz="0 0 0"
        rpy="0 0 0" />
      <geometry>
        <mesh
          filename="meshes/Right_Hip_Pitch.STL" />
      </geometry>
      <material
        name="">
        <color
          rgba="0.75294 0.75294 0.75294 1" />
      </material>
    </visual>
  </link>
  <joint
    name="Right_Hip_Pitch"
    type="revolute">
    <origin
      xyz="0 -0.096 -0.062"
      rpy="0 0 0" />
    <parent
      link="Trunk" />
    <child
      link="Right_Hip_Pitch" />
    <axis
      xyz="0 1 0" />
    <limit
      lower="-3.0"
      upper="2.21"
      effort="45"
      velocity="18"
    />
  </joint>
  <link
    name="Right_Hip_Roll">
    <inertial>
      <origin
        xyz="0.023585 0.000049 -0.024996"
        rpy="0 0 0" />
      <mass
        value="0.127825" />
      <inertia
        ixx="0.000191"
        ixy="0.000000"
        ixz="-0.000048"
        iyy="0.000262"
        iyz="0.000000"
        izz="0.000150" />
    </inertial>
    <visual>
      <origin
        xyz="0 0 0"
        rpy="0 0 0" />
      <geometry>
        <mesh
          filename="meshes/Right_Hip_Roll.STL" />
      </geometry>
      <material
        name="">
        <color
          rgba="0.75294 0.75294 0.75294 1" />
      </material>
    </visual>
    <collision>
      <origin
        xyz="0 0 0"
        rpy="0 1.5708 0" />
      <geometry>
        <cylinder radius="0.036" length="0.094" />
      </geometry>
    </collision>
  </link>
  <joint
    name="Right_Hip_Roll"
    type="revolute">
    <origin
      xyz="0 0 -0.026"
      rpy="0 0 0" />
    <parent
      link="Right_Hip_Pitch" />
    <child
      link="Right_Hip_Roll" />
    <axis
      xyz="1 0 0" />
    <limit
      lower="-1.57"
      upper="0.4"
      effort="30"
      velocity="18"
  />
  </joint>
  <link
    name="Right_Hip_Yaw">
    <inertial>
      <origin
        xyz="-0.008475 0.0040392 -0.087906"
        rpy="0 0 0" />
      <mass
        value="1.5592" />
      <inertia
        ixx="0.015786"
        ixy="-0.000096"
        ixz="0.001546"
        iyy="0.016140"
        iyz="-0.000745"
        izz="0.001551" />
    </inertial>
    <visual>
      <origin
        xyz="0 0 0"
        rpy="0 0 0" />
      <geometry>
        <mesh
          filename="meshes/Right_Hip_Yaw.STL" />
      </geometry>
      <material
        name="">
        <color
          rgba="0.75294 0.75294 0.75294 1" />
      </material>
    </visual>
    <collision>
      <origin
        xyz="0 0 -0.03"
        rpy="0 0 0" />
      <geometry>
        <cylinder radius="0.04" length="0.066" />
      </geometry>
    </collision>
  </link>
  <joint
    name="Right_Hip_Yaw"
    type="revolute">
    <origin
      xyz="0.012 0 -0.0485"
      rpy="0 0 0" />
    <parent
      link="Right_Hip_Roll" />
    <child
      link="Right_Hip_Yaw" />
    <axis
      xyz="0 0 1" />
    <limit
      lower="-1."
      upper="1."
      effort="30"
      velocity="18"
    />
  </joint>
  <link
    name="Right_Shank">
    <inertial>
      <origin
        xyz="-0.000805 -0.003146 -0.109215"
        rpy="0 0 0" />
      <mass
        value="1.483338" />
      <inertia
        ixx="0.023681"
        ixy="-0.000035"
        ixz="0.000221"
        iyy="0.023670"
        iyz="0.000105"
        izz="0.001240" />
    </inertial>
    <visual>
      <origin
        xyz="0 0 0"
        rpy="0 0 0" />
      <geometry>
        <mesh
          filename="meshes/Right_Shank.STL" />
      </geometry>
      <material
        name="">
        <color
          rgba="0.75294 0.75294 0.75294 1" />
      </material>
    </visual>
    <collision>
      <origin
        xyz="0 0 0"
        rpy="1.5708 0 0" />
      <geometry>
        <cylinder radius="0.045" length="0.07" />
      </geometry>
    </collision>
    <collision>
      <origin
        xyz="0 0 -0.13"
        rpy="0 0 0" />
      <geometry>
        <box size="0.06 0.06 0.1" />
      </geometry>
    </collision>
  </link>
  <joint
    name="Right_Knee_Pitch"
    type="revolute">
    <origin
      xyz="-0.014 0 -0.117"
      rpy="0 0 0" />
    <parent
      link="Right_Hip_Yaw" />
    <child
      link="Right_Shank" />
    <axis
      xyz="0 1 0" />
    <limit
      lower="0."
      upper="2.23"
      effort="45"
      velocity="18"
    />
  </joint>
  <link
    name="Right_Ankle_Cross">
    <inertial>
      <origin
        xyz="0.000000 0.000000 0.000000"
        rpy="0 0 0" />
      <mass
        value="0.038836" />
      <inertia
        ixx="0.000002"
        ixy="0.000000"
        ixz="0.000000"
        iyy="0.000004"
        iyz="0.000000"
        izz="0.000004" />
    </inertial>
    <visual>
      <origin
        xyz="0 0 0"
        rpy="0 0 0" />
      <geometry>
        <mesh
          filename="meshes/Right_Ankle_Cross.STL" />
      </geometry>
      <material
        name="">
        <color
          rgba="0.75294 0.75294 0.75294 1" />
      </material>
    </visual>
  </link>
  <joint
    name="Right_Ankle_Pitch"
    type="revolute">
    <origin
      xyz="0.00019706 -0.0002 -0.24519"
      rpy="0 0 0" />
    <parent
      link="Right_Shank" />
    <child
      link="Right_Ankle_Cross" />
    <axis
      xyz="0 1 0" />
    <limit
      lower="-0.87"
      upper="0.345"
      effort="20"
      velocity="18"
    />
  </joint>
  <link
    name="right_foot_link">
    <inertial>
      <origin
        xyz="-0.000178 -0.000002 -0.007291"
        rpy="0 0 0" />
      <mass
        value="0.386370" />
      <inertia
        ixx="0.000205"
        ixy="0.000000"
        ixz="-0.000054"
        iyy="0.000745"
        iyz="0.000000"
        izz="0.000790" />
    </inertial>
    <visual>
      <origin
        xyz="0 0 0"
        rpy="0 0 0" />
      <geometry>
        <mesh
          filename="meshes/Right_Foot.STL" />
      </geometry>
      <material
        name="">
        <color
          rgba="0.75294 0.75294 0.75294 1" />
      </material>
    </visual>
    <collision>
      <origin
        xyz="0 0 0"
        rpy="0 0 0" />
      <geometry>
        <mesh
          filename="meshes/Right_Foot.STL" />
      </geometry>
    </collision>
  </link>
  <joint
    name="Right_Ankle_Roll"
    type="revolute">
    <origin
      xyz="0 0 0"
      rpy="0 0 0" />
    <parent
      link="Right_Ankle_Cross" />
    <child
      link="right_foot_link" />
    <axis
      xyz="1 0 0" />
    <limit
      lower="-0.345"
      upper="0.345"
      effort="20"
      velocity="18"
    />
  </joint>
 
</robot>